2020-08-01 20:22:41,492 ERROR: Exception on /register [POST] [in /Users/macbook/site12/venv/lib/python3.8/site-packages/flask/app.py:1891]
Traceback (most recent call last):
  File "/Users/macbook/site12/venv/lib/python3.8/site-packages/flask/app.py", line 2447, in wsgi_app
    response = self.full_dispatch_request()
  File "/Users/macbook/site12/venv/lib/python3.8/site-packages/flask/app.py", line 1952, in full_dispatch_request
    rv = self.handle_user_exception(e)
  File "/Users/macbook/site12/venv/lib/python3.8/site-packages/flask/app.py", line 1821, in handle_user_exception
    reraise(exc_type, exc_value, tb)
  File "/Users/macbook/site12/venv/lib/python3.8/site-packages/flask/_compat.py", line 39, in reraise
    raise value
  File "/Users/macbook/site12/venv/lib/python3.8/site-packages/flask/app.py", line 1950, in full_dispatch_request
    rv = self.dispatch_request()
  File "/Users/macbook/site12/venv/lib/python3.8/site-packages/flask/app.py", line 1936, in dispatch_request
    return self.view_functions[rule.endpoint](**req.view_args)
  File "/Users/macbook/lang/flask_web_app/app/routes.py", line 43, in register
    user = User(username = form.username.data, email=form.email.data, language=form.my_language.data)
  File "<string>", line 4, in __init__
  File "/Users/macbook/site12/venv/lib/python3.8/site-packages/sqlalchemy/orm/state.py", line 433, in _initialize_instance
    manager.dispatch.init_failure(self, args, kwargs)
  File "/Users/macbook/site12/venv/lib/python3.8/site-packages/sqlalchemy/util/langhelpers.py", line 68, in __exit__
    compat.raise_(
  File "/Users/macbook/site12/venv/lib/python3.8/site-packages/sqlalchemy/util/compat.py", line 178, in raise_
    raise exception
  File "/Users/macbook/site12/venv/lib/python3.8/site-packages/sqlalchemy/orm/state.py", line 430, in _initialize_instance
    return manager.original_init(*mixed[1:], **kwargs)
  File "/Users/macbook/site12/venv/lib/python3.8/site-packages/sqlalchemy/ext/declarative/base.py", line 842, in _declarative_constructor
    setattr(self, k, kwargs[k])
  File "/Users/macbook/site12/venv/lib/python3.8/site-packages/sqlalchemy/orm/attributes.py", line 272, in __set__
    self.impl.set(
  File "/Users/macbook/site12/venv/lib/python3.8/site-packages/sqlalchemy/orm/attributes.py", line 1019, in set
    value = self.fire_replace_event(state, dict_, value, old, initiator)
  File "/Users/macbook/site12/venv/lib/python3.8/site-packages/sqlalchemy/orm/attributes.py", line 1041, in fire_replace_event
    value = fn(
  File "/Users/macbook/site12/venv/lib/python3.8/site-packages/sqlalchemy/orm/attributes.py", line 1451, in emit_backref_from_scalar_set_event
    instance_state(child),
AttributeError: 'int' object has no attribute '_sa_instance_state'
2020-08-01 20:23:50,090 INFO: Lang startup [in /Users/macbook/lang/flask_web_app/app/__init__.py:32]
2020-08-01 20:24:32,688 INFO: Lang startup [in /Users/macbook/lang/flask_web_app/app/__init__.py:32]
2020-08-01 20:41:37,812 INFO: Lang startup [in /Users/macbook/lang/flask_web_app/app/__init__.py:32]
2020-08-01 20:46:01,917 INFO: Lang startup [in /Users/macbook/lang/flask_web_app/app/__init__.py:32]
2020-08-01 20:46:48,044 ERROR: Exception on /register [POST] [in /Users/macbook/site12/venv/lib/python3.8/site-packages/flask/app.py:1891]
Traceback (most recent call last):
  File "/Users/macbook/site12/venv/lib/python3.8/site-packages/flask/app.py", line 2447, in wsgi_app
    response = self.full_dispatch_request()
  File "/Users/macbook/site12/venv/lib/python3.8/site-packages/flask/app.py", line 1952, in full_dispatch_request
    rv = self.handle_user_exception(e)
  File "/Users/macbook/site12/venv/lib/python3.8/site-packages/flask/app.py", line 1821, in handle_user_exception
    reraise(exc_type, exc_value, tb)
  File "/Users/macbook/site12/venv/lib/python3.8/site-packages/flask/_compat.py", line 39, in reraise
    raise value
  File "/Users/macbook/site12/venv/lib/python3.8/site-packages/flask/app.py", line 1950, in full_dispatch_request
    rv = self.dispatch_request()
  File "/Users/macbook/site12/venv/lib/python3.8/site-packages/flask/app.py", line 1936, in dispatch_request
    return self.view_functions[rule.endpoint](**req.view_args)
  File "/Users/macbook/lang/flask_web_app/app/routes.py", line 46, in register
    user = User(username = form.username.data, email=form.email.data, language_id=language.id)
AttributeError: 'NoneType' object has no attribute 'id'
2020-08-01 20:47:51,006 INFO: Lang startup [in /Users/macbook/lang/flask_web_app/app/__init__.py:32]
2020-08-01 20:51:49,998 INFO: Lang startup [in /Users/macbook/lang/flask_web_app/app/__init__.py:32]
2020-08-01 20:52:31,173 ERROR: Exception on /register [POST] [in /Users/macbook/site12/venv/lib/python3.8/site-packages/flask/app.py:1891]
Traceback (most recent call last):
  File "/Users/macbook/site12/venv/lib/python3.8/site-packages/flask/app.py", line 2447, in wsgi_app
    response = self.full_dispatch_request()
  File "/Users/macbook/site12/venv/lib/python3.8/site-packages/flask/app.py", line 1952, in full_dispatch_request
    rv = self.handle_user_exception(e)
  File "/Users/macbook/site12/venv/lib/python3.8/site-packages/flask/app.py", line 1821, in handle_user_exception
    reraise(exc_type, exc_value, tb)
  File "/Users/macbook/site12/venv/lib/python3.8/site-packages/flask/_compat.py", line 39, in reraise
    raise value
  File "/Users/macbook/site12/venv/lib/python3.8/site-packages/flask/app.py", line 1950, in full_dispatch_request
    rv = self.dispatch_request()
  File "/Users/macbook/site12/venv/lib/python3.8/site-packages/flask/app.py", line 1936, in dispatch_request
    return self.view_functions[rule.endpoint](**req.view_args)
  File "/Users/macbook/lang/flask_web_app/app/routes.py", line 44, in register
    language = Language.query.filter_by(language=form.my_language.data).first().id
AttributeError: 'NoneType' object has no attribute 'id'
