2020-09-03 00:58:26,522 ERROR: Exception on /edit_profile [POST] [in /Users/macbook/site12/venv/lib/python3.8/site-packages/flask/app.py:1891]
Traceback (most recent call last):
  File "/Users/macbook/site12/venv/lib/python3.8/site-packages/flask/app.py", line 2447, in wsgi_app
    response = self.full_dispatch_request()
  File "/Users/macbook/site12/venv/lib/python3.8/site-packages/flask/app.py", line 1952, in full_dispatch_request
    rv = self.handle_user_exception(e)
  File "/Users/macbook/site12/venv/lib/python3.8/site-packages/flask/app.py", line 1821, in handle_user_exception
    reraise(exc_type, exc_value, tb)
  File "/Users/macbook/site12/venv/lib/python3.8/site-packages/flask/_compat.py", line 39, in reraise
    raise value
  File "/Users/macbook/site12/venv/lib/python3.8/site-packages/flask/app.py", line 1950, in full_dispatch_request
    rv = self.dispatch_request()
  File "/Users/macbook/site12/venv/lib/python3.8/site-packages/flask/app.py", line 1936, in dispatch_request
    return self.view_functions[rule.endpoint](**req.view_args)
  File "/Users/macbook/site12/venv/lib/python3.8/site-packages/flask_login/utils.py", line 272, in decorated_view
    return func(*args, **kwargs)
  File "/Users/macbook/lang/flask_web_app/app/routes.py", line 105, in edit_profile
    dictionary = Dictionary(user_id = currrent_user.id, language_id = form.languages.data)
NameError: name 'currrent_user' is not defined
2020-09-03 00:58:47,372 INFO: Lang startup [in /Users/macbook/lang/flask_web_app/app/__init__.py:32]
2020-09-03 01:00:24,433 INFO: Lang startup [in /Users/macbook/lang/flask_web_app/app/__init__.py:32]
2020-09-03 01:02:42,998 INFO: Lang startup [in /Users/macbook/lang/flask_web_app/app/__init__.py:32]
2020-09-03 01:04:41,971 INFO: Lang startup [in /Users/macbook/lang/flask_web_app/app/__init__.py:32]
2020-09-03 01:04:59,040 INFO: Lang startup [in /Users/macbook/lang/flask_web_app/app/__init__.py:32]
2020-09-03 01:05:26,295 INFO: Lang startup [in /Users/macbook/lang/flask_web_app/app/__init__.py:32]
2020-09-03 01:08:14,730 INFO: Lang startup [in /Users/macbook/lang/flask_web_app/app/__init__.py:32]
2020-09-03 22:37:26,793 INFO: Lang startup [in /Users/macbook/lang/flask_web_app/app/__init__.py:32]
2020-09-03 22:42:28,570 INFO: Lang startup [in /Users/macbook/lang/flask_web_app/app/__init__.py:32]
2020-09-03 22:42:32,605 ERROR: Exception on /mywords/ [GET] [in /Users/macbook/site12/venv/lib/python3.8/site-packages/flask/app.py:1891]
Traceback (most recent call last):
  File "/Users/macbook/site12/venv/lib/python3.8/site-packages/flask/app.py", line 2447, in wsgi_app
    response = self.full_dispatch_request()
  File "/Users/macbook/site12/venv/lib/python3.8/site-packages/flask/app.py", line 1952, in full_dispatch_request
    rv = self.handle_user_exception(e)
  File "/Users/macbook/site12/venv/lib/python3.8/site-packages/flask/app.py", line 1821, in handle_user_exception
    reraise(exc_type, exc_value, tb)
  File "/Users/macbook/site12/venv/lib/python3.8/site-packages/flask/_compat.py", line 39, in reraise
    raise value
  File "/Users/macbook/site12/venv/lib/python3.8/site-packages/flask/app.py", line 1950, in full_dispatch_request
    rv = self.dispatch_request()
  File "/Users/macbook/site12/venv/lib/python3.8/site-packages/flask/app.py", line 1936, in dispatch_request
    return self.view_functions[rule.endpoint](**req.view_args)
  File "/Users/macbook/site12/venv/lib/python3.8/site-packages/flask_login/utils.py", line 272, in decorated_view
    return func(*args, **kwargs)
  File "/Users/macbook/lang/flask_web_app/app/routes.py", line 94, in mywords
    return render_template('mywords.html',title = 'Dictionary', words = words.items, next_url = next_url , previous_url = previous_url, form=dictionaryForm)
  File "/Users/macbook/site12/venv/lib/python3.8/site-packages/flask/templating.py", line 137, in render_template
    return _render(
  File "/Users/macbook/site12/venv/lib/python3.8/site-packages/flask/templating.py", line 120, in _render
    rv = template.render(context)
  File "/Users/macbook/site12/venv/lib/python3.8/site-packages/jinja2/environment.py", line 1090, in render
    self.environment.handle_exception()
  File "/Users/macbook/site12/venv/lib/python3.8/site-packages/jinja2/environment.py", line 832, in handle_exception
    reraise(*rewrite_traceback_stack(source=source))
  File "/Users/macbook/site12/venv/lib/python3.8/site-packages/jinja2/_compat.py", line 28, in reraise
    raise value.with_traceback(tb)
  File "/Users/macbook/lang/flask_web_app/app/templates/mywords.html", line 2, in top-level template code
    {% import 'bootstrap/wtf.html' as wtf %}
  File "/Users/macbook/lang/flask_web_app/app/templates/base.html", line 2, in top-level template code
    {% extends 'bootstrap/base.html' %}
  File "/Users/macbook/site12/venv/lib/python3.8/site-packages/flask_bootstrap/templates/bootstrap/base.html", line 1, in top-level template code
    {% block doc -%}
  File "/Users/macbook/site12/venv/lib/python3.8/site-packages/flask_bootstrap/templates/bootstrap/base.html", line 4, in block "doc"
    {%- block html %}
  File "/Users/macbook/site12/venv/lib/python3.8/site-packages/flask_bootstrap/templates/bootstrap/base.html", line 20, in block "html"
    {% block body -%}
  File "/Users/macbook/site12/venv/lib/python3.8/site-packages/flask_bootstrap/templates/bootstrap/base.html", line 23, in block "body"
    {% block content -%}
  File "/Users/macbook/lang/flask_web_app/app/templates/base.html", line 52, in block "content"
    {% block app_content %}{% endblock %}
  File "/Users/macbook/lang/flask_web_app/app/templates/mywords.html", line 5, in block "app_content"
    {{ form.csrf-token }}
jinja2.exceptions.UndefinedError: 'app.forms.DictionaryForm object' has no attribute 'csrf'
2020-09-03 22:42:59,224 INFO: Lang startup [in /Users/macbook/lang/flask_web_app/app/__init__.py:32]
2020-09-03 22:44:58,529 INFO: Lang startup [in /Users/macbook/lang/flask_web_app/app/__init__.py:32]
2020-09-03 22:45:10,809 ERROR: Exception on /mywords/ [POST] [in /Users/macbook/site12/venv/lib/python3.8/site-packages/flask/app.py:1891]
Traceback (most recent call last):
  File "/Users/macbook/site12/venv/lib/python3.8/site-packages/flask/app.py", line 2447, in wsgi_app
    response = self.full_dispatch_request()
  File "/Users/macbook/site12/venv/lib/python3.8/site-packages/flask/app.py", line 1952, in full_dispatch_request
    rv = self.handle_user_exception(e)
  File "/Users/macbook/site12/venv/lib/python3.8/site-packages/flask/app.py", line 1821, in handle_user_exception
    reraise(exc_type, exc_value, tb)
  File "/Users/macbook/site12/venv/lib/python3.8/site-packages/flask/_compat.py", line 39, in reraise
    raise value
  File "/Users/macbook/site12/venv/lib/python3.8/site-packages/flask/app.py", line 1950, in full_dispatch_request
    rv = self.dispatch_request()
  File "/Users/macbook/site12/venv/lib/python3.8/site-packages/flask/app.py", line 1936, in dispatch_request
    return self.view_functions[rule.endpoint](**req.view_args)
  File "/Users/macbook/site12/venv/lib/python3.8/site-packages/flask_login/utils.py", line 272, in decorated_view
    return func(*args, **kwargs)
  File "/Users/macbook/lang/flask_web_app/app/routes.py", line 76, in mywords
    words = current_user.languages[languageid].words.paginate(
  File "/Users/macbook/site12/venv/lib/python3.8/site-packages/sqlalchemy/orm/dynamic.py", line 323, in __getitem__
    return self._clone(sess).__getitem__(index)
  File "/Users/macbook/site12/venv/lib/python3.8/site-packages/sqlalchemy/orm/query.py", line 3154, in __getitem__
    return list(self[item : item + 1])[0]
IndexError: list index out of range
2020-09-03 22:45:20,960 ERROR: Exception on /mywords/ [POST] [in /Users/macbook/site12/venv/lib/python3.8/site-packages/flask/app.py:1891]
Traceback (most recent call last):
  File "/Users/macbook/site12/venv/lib/python3.8/site-packages/flask/app.py", line 2447, in wsgi_app
    response = self.full_dispatch_request()
  File "/Users/macbook/site12/venv/lib/python3.8/site-packages/flask/app.py", line 1952, in full_dispatch_request
    rv = self.handle_user_exception(e)
  File "/Users/macbook/site12/venv/lib/python3.8/site-packages/flask/app.py", line 1821, in handle_user_exception
    reraise(exc_type, exc_value, tb)
  File "/Users/macbook/site12/venv/lib/python3.8/site-packages/flask/_compat.py", line 39, in reraise
    raise value
  File "/Users/macbook/site12/venv/lib/python3.8/site-packages/flask/app.py", line 1950, in full_dispatch_request
    rv = self.dispatch_request()
  File "/Users/macbook/site12/venv/lib/python3.8/site-packages/flask/app.py", line 1936, in dispatch_request
    return self.view_functions[rule.endpoint](**req.view_args)
  File "/Users/macbook/site12/venv/lib/python3.8/site-packages/flask_login/utils.py", line 272, in decorated_view
    return func(*args, **kwargs)
  File "/Users/macbook/lang/flask_web_app/app/routes.py", line 76, in mywords
    words = current_user.languages[languageid].words.paginate(
  File "/Users/macbook/site12/venv/lib/python3.8/site-packages/sqlalchemy/orm/dynamic.py", line 323, in __getitem__
    return self._clone(sess).__getitem__(index)
  File "/Users/macbook/site12/venv/lib/python3.8/site-packages/sqlalchemy/orm/query.py", line 3154, in __getitem__
    return list(self[item : item + 1])[0]
IndexError: list index out of range
